<?xml version="1.0"?>
<!-- Open_Manipulator Chain -->
<robot name="cjs_robot" xmlns:xacro="http://ros.org/wiki/xacro">

  <!-- Import all Gazebo-customization elements, including Gazebo colors -->
  <xacro:include filename="$(find cjs_robot_description)/urdf/open_manipulator.gazebo.xacro" />
  <!-- Import Rviz colors -->
  <xacro:include filename="$(find cjs_robot_description)/urdf/materials.xacro" />

  <!-- Transmission macro -->
  <xacro:macro name="SimpleTransmission" params="joint n">
    <transmission name="tran${n}">
      <type>transmission_interface/SimpleTransmission</type>
      <joint name="${joint}">
        <hardwareInterface>hardware_interface/PositionJointInterface</hardwareInterface>
      </joint>
      <actuator name="motor${n}">
        <hardwareInterface>hardware_interface/PositionJointInterface</hardwareInterface>
        <mechanicalReduction>1</mechanicalReduction>
      </actuator>
    </transmission>
  </xacro:macro>

  <!-- World -->
  <link name="world">
  </link>

  <!-- World fixed joint-->
  <joint name="world_fixed" type="fixed">
    <origin xyz="0 0 0" rpy="0 0 0"/>
    <parent link="world"/>
    <child link="link1"/>
  </joint>

  <!-- Link 1 -->
  <link name="link1">
    <visual>
      <origin xyz="0 0 0" rpy="0 0 0"/>
      <geometry>
        <mesh filename="package://robotis_description/meshes/chain_link1.stl" scale="0.001 0.001 0.001"/>
      </geometry>
      <material name="grey"/>
    </visual>

    <collision>
      <origin xyz="0 0 0" rpy="0 0 0"/>
      <geometry>
        <mesh filename="package://robotis_description/meshes/chain_link1.stl" scale="0.001 0.001 0.001"/>
      </geometry>
    </collision>

<!--    <inertial>
      <origin xyz="0 0 0" />
      <mass value="0.082" />
      <inertia ixx="0.1" ixy="0.0" ixz="0.0"
               iyy="0.1" iyz="0.0"
               izz="0.1" />
    </inertial>-->

     <inertial>
      <origin xyz="3.0876154e-04 0.0000000e+00 -1.2176461e-04" />
      <mass value="7.9119962e-02" />
      <inertia ixx="1.2505234e-05" ixy="0.0" ixz="-1.7855208e-07"
               iyy="2.1898364e-05" iyz="0.0"
               izz="1.9267361e-05" />
    </inertial>
  </link>

  <!-- Joint 1 -->
  <joint name="joint1" type="revolute">
    <parent link="link1"/>
    <child link="link2"/>
    <origin xyz="0.012 0.0 0.017" rpy="0 0 0"/>
    <axis xyz="0 0 1"/>
<!--
    <limit velocity="4.8" effort="1" lower="${-pi*0.9}" upper="${pi*0.9}" />
-->
    <limit velocity="4.8" effort="1" lower="-2.8274328" upper="2.8274328" />

  </joint>

  <!-- Transmission 1 -->
  <xacro:SimpleTransmission n="1" joint="joint1" />

  <!--  Link 2 -->
  <link name="link2">
    <visual>
      <origin xyz="0 0 0.019" rpy="0 0 0"/>
      <geometry>
        <mesh filename="package://robotis_description/meshes/chain_link2.stl" scale="0.001 0.001 0.001"/>
      </geometry>
      <material name="grey"/>
    </visual>

    <collision>
      <origin xyz="0 0 0.019" rpy="0 0 0"/>
      <geometry>
        <mesh filename="package://robotis_description/meshes/chain_link2.stl" scale="0.001 0.001 0.001"/>
      </geometry>
    </collision>

<!--    <inertial>
      <origin xyz="0 0 0" />
      <mass value="0.098" />
      <inertia ixx="0.1" ixy="0.0" ixz="0.0"
               iyy="0.1" iyz="0.0"
               izz="0.1" />
    </inertial>-->

     <inertial>
<!--
      <origin xyz="-3.0184870e-04 5.4043684e-04 ${0.018 + 2.9433464e-02}" />
-->
      <origin xyz="-3.0184870e-04 5.4043684e-04 0.047433464" />
      <mass value="9.8406837e-02" />
      <inertia ixx="3.4543422e-05" ixy="-1.6031095e-08" ixz="-3.8375155e-07"
               iyy="3.2689329e-05" iyz="2.8511935e-08"
               izz="1.8850320e-05" />
    </inertial>
  </link>

<!--
  <gazebo>
    <plugin name="gazebo_ros_control" filename="libgazebo_ros_control.so">
      <robotNamespace>/robotis</robotNamespace>
      <controlPeriod>0.001</controlPeriod>
      <robotSimType>gazebo_ros_control/DefaultRobotHWSim</robotSimType>
      <legacyModeNS>true</legacyModeNS>
    </plugin>
  </gazebo>
-->

</robot>
